Workbook

Sheet Detalle de Costos
D3: Costos por paquete de trabajo
A6: Segmentación de mercado para Targeting
A7: SMT - 2026 - 1 | B7: Paquete de Trabajo
A8: Semanas | C8: 1 | D8: 2 | E8: 3 | F8: 4 | G8: 5 | H8: 6 | I8: 7 | J8: 8 | K8: 9 | L8: 10 | M8: 11 | N8: 12
A9: Preparación y Exploración Inicial de Datos
A10: 1.1 | B10: Configuración del Entorno y Kick-off | C10: 0
A11: 1.1.1 | B11: Reunión de planificación del Sprint 1 | C11: 800
A12: 1.1.2 | B12: Configuración de herramientas colaborativas | C12: 1200
A13: 1.1.3 | B13: Verificación de acceso a recursos | C13: 1000
A14: 1.1.4 | B14: Documentación de autorizaciones institucionales | C14: 1500
A15: 1.2 | B15: Comprensión del Contexto del Negocio y los Datos
A16: 1.2.1 | B16: Análisis del problema de negocio | C16: 1800
A17: 1.2.2 | B17: Definición de segmento desde perspectiva de negocio | C17: 1700
A18: 1.2.3 | B18: Elaboración de diccionario de datos | C18: 2000
A19: 1.3 | B19: Carga y Exploración Estructural de Datos
A20: 1.3.1 | B20: Configuración del notebook en Google Colab | C20: 1500
A21: 1.3.2 | B21: Exploración inicial de la estructura | D21: 2000
A22: 1.3.3 | B22: Identificación de valores nulos y duplicados | D22: 2000
A23: 1.3.4 | B23: Estadísticos descriptivos básicos | D23: 2000
A24: 1.4 | B24: Documentación y Cierre del Sprint 1
A25: 1.4.1 | B25: Limpieza y comentarios del notebook | D25: 3000
A26: 1.4.2 | B26: Elaboración de reporte de avance | D26: 3500
A27: 1.4.3 | B27: Actualización de bitácora y tablero Kanban | D27: 2000
A28: 1.4.4 | B28: Reunión de revisión preliminar con profesor | D28: 4000
A29: EDA Completo, Determinación de Clusters e Inicio de Modelado
A30: 2.1 | B30: Análisis Univariado con Visualizaciones
A31: 2.1.1 | B31: Análisis de variable Gender | E31: 2000
A32: 2.1.2 | B32: Análisis de variable Age | E32: 2500
A33: 2.1.3 | B33: Análisis de variable Annual Income | E33: 2500
A34: 2.1.4 | B34: Análisis de variable Spending Score | E34: 2000
A35: 2.2 | B35: Análisis Bivariado y Correlaciones
A36: 2.2.1 | B36: Creación de matriz de correlación | E36: 2500
A37: 2.2.2 | B37: Heatmap visual de correlaciones | E37: 2500
A38: 2.2.3 | B38: Scatter plots de relaciones clave | F38: 3000
A39: 2.2.4 | B39: Identificación de variables clave | F39: 2000
A40: 2.3 | B40: Determinación del Número Óptimo de Clusters
A41: 2.3.1 | B41: Método del codo (Elbow) | F41: 3000
A42: 2.3.2 | B42: Silhouette Score | F42: 3000
A43: 2.3.3 | B43: Validación cualitativa del equipo | F43: 3000
A44: 2.4 | B44: Preparación de Datos para Modelado
...

Sheet Plantilla Curva S
C7: Curva S de Recursos
C9: Proyecto: | D9: Nombre del Proyecto
C10: ID: | D10: Código identificador del proyecto.
C11: Fecha de Inicio | D11: 46069 | F11: Fecha Fin: | H11: 46150 | K11: Fecha de Corte: | M11: 46094
D13: Semana
D14: 1 | E14: 2 | F14: 3 | G14: 4 | H14: 5 | I14: 6 | J14: 7 | K14: 8 | L14: 9 | M14: 10 | N14: 11 | O14: 12
C15: Valor Planificado | D15: ='Detalle de Costos'!C137 -> 11500 | E15: ='Detalle de Costos'!D137 -> 18500 | F15: ='Detalle de Costos'!E137 -> 14000 | G15: ='Detalle de Costos'!F137 -> 31000 | H15: ='Detalle de Costos'!G137 -> 33000 | I15: ='Detalle de Costos'!H137 -> 42000 | J15: ='Detalle de Costos'!I137 -> 36000 | K15: ='Detalle de Costos'!J137 -> 39000 | ... O15: ='Detalle de Costos'!N137 -> 19000
C16: Valor Planificado Acumulado | D16: =D15 -> 11500 | E16: =E15+D16 -> 30000 | F16: =F15+E16 -> 44000 | G16: =G15+F16 -> 75000 | H16: =H15+G16 -> 108000 | I16: =I15+H16 -> 150000 | J16: =J15+I16 -> 186000 | K16: =K15+J16 -> 225000 | L16: =L15+K16 -> 245000 | ... O16: =O15+N16 -> 300000
C17: Costo Real | D17: 8000 | E17: 12000 | F17: 18000 | G17: 25000
C18: Costo Real Acumulado | D18: =D17 -> 8000 | E18: =D17+E17 -> 20000 | F18: =E17+F17 -> 30000 | G18: =F17+G17 -> 43000
